2020-04-29 19:23:22,904 - Client_Library - ERROR - Refresh token not provided!; Exception Message::Error occurred for https://www.zohoapis.com/crm/v2/Leads/803228000003710001. Error Code: 0 Response error_content: None. Error Details::['  File "test.py", line 20, in <module>\n    lest_response = lead_record_instance.get()\n', '  File "/Users/erik/VirtEnvPython/VirtEnvPy/lib/python3.7/site-packages/zcrmsdk/Operations.py", line 303, in get\n    return EntityAPIHandler.get_instance(self).get_record()\n', '  File "/Users/erik/VirtEnvPython/VirtEnvPy/lib/python3.7/site-packages/zcrmsdk/Handler.py", line 59, in get_record\n    apiResponse=APIRequest(handler_ins).get_api_response()\n', '  File "/Users/erik/VirtEnvPython/VirtEnvPy/lib/python3.7/site-packages/zcrmsdk/Request.py", line 58, in get_api_response\n    CommonUtil.raise_exception(self.url,ex.message,traceback.format_stack())\n']
2020-04-29 19:23:30,319 - Client_Library - ERROR - Refresh token not provided!; Exception Message::Error occurred for https://www.zohoapis.com/crm/v2/Leads/803228000003710001. Error Code: 0 Response error_content: None. Error Details::['  File "test.py", line 20, in <module>\n    lest_response = lead_record_instance.get()\n', '  File "/Users/erik/VirtEnvPython/VirtEnvPy/lib/python3.7/site-packages/zcrmsdk/Operations.py", line 303, in get\n    return EntityAPIHandler.get_instance(self).get_record()\n', '  File "/Users/erik/VirtEnvPython/VirtEnvPy/lib/python3.7/site-packages/zcrmsdk/Handler.py", line 59, in get_record\n    apiResponse=APIRequest(handler_ins).get_api_response()\n', '  File "/Users/erik/VirtEnvPython/VirtEnvPy/lib/python3.7/site-packages/zcrmsdk/Request.py", line 58, in get_api_response\n    CommonUtil.raise_exception(self.url,ex.message,traceback.format_stack())\n']
2020-04-29 19:23:36,507 - Client_Library - ERROR - Refresh token not provided!; Exception Message::Error occurred for https://www.zohoapis.com/crm/v2/Leads/803228000003710001. Error Code: 0 Response error_content: None. Error Details::['  File "test.py", line 20, in <module>\n    lest_response = lead_record_instance.get()\n', '  File "/Users/erik/VirtEnvPython/VirtEnvPy/lib/python3.7/site-packages/zcrmsdk/Operations.py", line 303, in get\n    return EntityAPIHandler.get_instance(self).get_record()\n', '  File "/Users/erik/VirtEnvPython/VirtEnvPy/lib/python3.7/site-packages/zcrmsdk/Handler.py", line 59, in get_record\n    apiResponse=APIRequest(handler_ins).get_api_response()\n', '  File "/Users/erik/VirtEnvPython/VirtEnvPy/lib/python3.7/site-packages/zcrmsdk/Request.py", line 58, in get_api_response\n    CommonUtil.raise_exception(self.url,ex.message,traceback.format_stack())\n']
2020-04-29 19:23:57,739 - Client_Library - ERROR - Refresh token not provided!; Exception Message::Error occurred for https://www.zohoapis.com/crm/v2/Leads/803228000003710001. Error Code: 0 Response error_content: None. Error Details::['  File "test.py", line 20, in <module>\n    lest_response = lead_record_instance.get()\n', '  File "/Users/erik/VirtEnvPython/VirtEnvPy/lib/python3.7/site-packages/zcrmsdk/Operations.py", line 303, in get\n    return EntityAPIHandler.get_instance(self).get_record()\n', '  File "/Users/erik/VirtEnvPython/VirtEnvPy/lib/python3.7/site-packages/zcrmsdk/Handler.py", line 59, in get_record\n    apiResponse=APIRequest(handler_ins).get_api_response()\n', '  File "/Users/erik/VirtEnvPython/VirtEnvPy/lib/python3.7/site-packages/zcrmsdk/Request.py", line 58, in get_api_response\n    CommonUtil.raise_exception(self.url,ex.message,traceback.format_stack())\n']
2020-04-29 19:24:10,678 - Client_Library - ERROR - Refresh token not provided!; Exception Message::Error occurred for https://www.zohoapis.com/crm/v2/Leads/803228000003710001. Error Code: 0 Response error_content: None. Error Details::['  File "test.py", line 20, in <module>\n    lest_response = lead_record_instance.get()\n', '  File "/Users/erik/VirtEnvPython/VirtEnvPy/lib/python3.7/site-packages/zcrmsdk/Operations.py", line 303, in get\n    return EntityAPIHandler.get_instance(self).get_record()\n', '  File "/Users/erik/VirtEnvPython/VirtEnvPy/lib/python3.7/site-packages/zcrmsdk/Handler.py", line 59, in get_record\n    apiResponse=APIRequest(handler_ins).get_api_response()\n', '  File "/Users/erik/VirtEnvPython/VirtEnvPy/lib/python3.7/site-packages/zcrmsdk/Request.py", line 58, in get_api_response\n    CommonUtil.raise_exception(self.url,ex.message,traceback.format_stack())\n']
2020-04-29 19:24:14,499 - Client_Library - ERROR - Refresh token not provided!; Exception Message::Error occurred for https://www.zohoapis.com/crm/v2/Leads/803228000003710001. Error Code: 0 Response error_content: None. Error Details::['  File "test.py", line 20, in <module>\n    lest_response = lead_record_instance.get()\n', '  File "/Users/erik/VirtEnvPython/VirtEnvPy/lib/python3.7/site-packages/zcrmsdk/Operations.py", line 303, in get\n    return EntityAPIHandler.get_instance(self).get_record()\n', '  File "/Users/erik/VirtEnvPython/VirtEnvPy/lib/python3.7/site-packages/zcrmsdk/Handler.py", line 59, in get_record\n    apiResponse=APIRequest(handler_ins).get_api_response()\n', '  File "/Users/erik/VirtEnvPython/VirtEnvPy/lib/python3.7/site-packages/zcrmsdk/Request.py", line 58, in get_api_response\n    CommonUtil.raise_exception(self.url,ex.message,traceback.format_stack())\n']
2020-04-29 19:25:32,772 - Client_Library - ERROR - Refresh token not provided!; Exception Message::Error occurred for https://www.zohoapis.com/crm/v2/Leads/803228000003710001. Error Code: 0 Response error_content: None. Error Details::['  File "test.py", line 20, in <module>\n    lest_response = lead_record_instance.get()\n', '  File "/Users/erik/VirtEnvPython/VirtEnvPy/lib/python3.7/site-packages/zcrmsdk/Operations.py", line 303, in get\n    return EntityAPIHandler.get_instance(self).get_record()\n', '  File "/Users/erik/VirtEnvPython/VirtEnvPy/lib/python3.7/site-packages/zcrmsdk/Handler.py", line 59, in get_record\n    apiResponse=APIRequest(handler_ins).get_api_response()\n', '  File "/Users/erik/VirtEnvPython/VirtEnvPy/lib/python3.7/site-packages/zcrmsdk/Request.py", line 58, in get_api_response\n    CommonUtil.raise_exception(self.url,ex.message,traceback.format_stack())\n']
2020-04-29 19:25:35,871 - Client_Library - ERROR - Refresh token not provided!; Exception Message::Error occurred for https://www.zohoapis.com/crm/v2/Leads/803228000003710001. Error Code: 0 Response error_content: None. Error Details::['  File "test.py", line 20, in <module>\n    lest_response = lead_record_instance.get()\n', '  File "/Users/erik/VirtEnvPython/VirtEnvPy/lib/python3.7/site-packages/zcrmsdk/Operations.py", line 303, in get\n    return EntityAPIHandler.get_instance(self).get_record()\n', '  File "/Users/erik/VirtEnvPython/VirtEnvPy/lib/python3.7/site-packages/zcrmsdk/Handler.py", line 59, in get_record\n    apiResponse=APIRequest(handler_ins).get_api_response()\n', '  File "/Users/erik/VirtEnvPython/VirtEnvPy/lib/python3.7/site-packages/zcrmsdk/Request.py", line 58, in get_api_response\n    CommonUtil.raise_exception(self.url,ex.message,traceback.format_stack())\n']
2020-04-29 19:25:41,693 - Client_Library - ERROR - Refresh token not provided!; Exception Message::Error occurred for https://www.zohoapis.com/crm/v2/Leads/803228000003710001. Error Code: 0 Response error_content: None. Error Details::['  File "test.py", line 19, in <module>\n    lest_response = lead_record_instance.get()\n', '  File "/Users/erik/VirtEnvPython/VirtEnvPy/lib/python3.7/site-packages/zcrmsdk/Operations.py", line 303, in get\n    return EntityAPIHandler.get_instance(self).get_record()\n', '  File "/Users/erik/VirtEnvPython/VirtEnvPy/lib/python3.7/site-packages/zcrmsdk/Handler.py", line 59, in get_record\n    apiResponse=APIRequest(handler_ins).get_api_response()\n', '  File "/Users/erik/VirtEnvPython/VirtEnvPy/lib/python3.7/site-packages/zcrmsdk/Request.py", line 58, in get_api_response\n    CommonUtil.raise_exception(self.url,ex.message,traceback.format_stack())\n']
2020-04-29 19:28:34,672 - Client_Library - ERROR - Refresh token not provided!; Exception Message::Error occurred for https://www.zohoapis.com/crm/v2/Leads/803228000003710001. Error Code: 0 Response error_content: None. Error Details::['  File "test.py", line 20, in <module>\n    lead_response = lead_record_instance.get()\n', '  File "/Users/erik/VirtEnvPython/VirtEnvPy/lib/python3.7/site-packages/zcrmsdk/Operations.py", line 303, in get\n    return EntityAPIHandler.get_instance(self).get_record()\n', '  File "/Users/erik/VirtEnvPython/VirtEnvPy/lib/python3.7/site-packages/zcrmsdk/Handler.py", line 59, in get_record\n    apiResponse=APIRequest(handler_ins).get_api_response()\n', '  File "/Users/erik/VirtEnvPython/VirtEnvPy/lib/python3.7/site-packages/zcrmsdk/Request.py", line 58, in get_api_response\n    CommonUtil.raise_exception(self.url,ex.message,traceback.format_stack())\n']
2020-04-29 19:28:39,100 - Client_Library - ERROR - Refresh token not provided!; Exception Message::Error occurred for https://www.zohoapis.com/crm/v2/Leads/803228000003710001. Error Code: 0 Response error_content: None. Error Details::['  File "test.py", line 20, in <module>\n    lead_response = lead_record_instance.get()\n', '  File "/Users/erik/VirtEnvPython/VirtEnvPy/lib/python3.7/site-packages/zcrmsdk/Operations.py", line 303, in get\n    return EntityAPIHandler.get_instance(self).get_record()\n', '  File "/Users/erik/VirtEnvPython/VirtEnvPy/lib/python3.7/site-packages/zcrmsdk/Handler.py", line 59, in get_record\n    apiResponse=APIRequest(handler_ins).get_api_response()\n', '  File "/Users/erik/VirtEnvPython/VirtEnvPy/lib/python3.7/site-packages/zcrmsdk/Request.py", line 58, in get_api_response\n    CommonUtil.raise_exception(self.url,ex.message,traceback.format_stack())\n']
2020-04-29 19:28:57,859 - Client_Library - ERROR - Refresh token not provided!; Exception Message::Error occurred for https://www.zohoapis.com/crm/v2/Leads/803228000003710001. Error Code: 0 Response error_content: None. Error Details::['  File "test.py", line 20, in <module>\n    lead_response = lead_record_instance.get()\n', '  File "/Users/erik/VirtEnvPython/VirtEnvPy/lib/python3.7/site-packages/zcrmsdk/Operations.py", line 303, in get\n    return EntityAPIHandler.get_instance(self).get_record()\n', '  File "/Users/erik/VirtEnvPython/VirtEnvPy/lib/python3.7/site-packages/zcrmsdk/Handler.py", line 59, in get_record\n    apiResponse=APIRequest(handler_ins).get_api_response()\n', '  File "/Users/erik/VirtEnvPython/VirtEnvPy/lib/python3.7/site-packages/zcrmsdk/Request.py", line 58, in get_api_response\n    CommonUtil.raise_exception(self.url,ex.message,traceback.format_stack())\n']
2020-04-29 19:29:03,088 - Client_Library - ERROR - Refresh token not provided!; Exception Message::Error occurred for https://www.zohoapis.com/crm/v2/Leads/803228000003710001. Error Code: 0 Response error_content: None. Error Details::['  File "test.py", line 20, in <module>\n    lead_response = lead_record_instance.get()\n', '  File "/Users/erik/VirtEnvPython/VirtEnvPy/lib/python3.7/site-packages/zcrmsdk/Operations.py", line 303, in get\n    return EntityAPIHandler.get_instance(self).get_record()\n', '  File "/Users/erik/VirtEnvPython/VirtEnvPy/lib/python3.7/site-packages/zcrmsdk/Handler.py", line 59, in get_record\n    apiResponse=APIRequest(handler_ins).get_api_response()\n', '  File "/Users/erik/VirtEnvPython/VirtEnvPy/lib/python3.7/site-packages/zcrmsdk/Request.py", line 58, in get_api_response\n    CommonUtil.raise_exception(self.url,ex.message,traceback.format_stack())\n']
2020-04-29 19:30:03,860 - Client_Library - ERROR - Refresh token not provided!; Exception Message::Error occurred for https://www.zohoapis.com/crm/v2/Leads/803228000003710001. Error Code: 0 Response error_content: None. Error Details::['  File "test.py", line 20, in <module>\n    lead_response = lead_record_instance.get()\n', '  File "/Users/erik/VirtEnvPython/VirtEnvPy/lib/python3.7/site-packages/zcrmsdk/Operations.py", line 303, in get\n    return EntityAPIHandler.get_instance(self).get_record()\n', '  File "/Users/erik/VirtEnvPython/VirtEnvPy/lib/python3.7/site-packages/zcrmsdk/Handler.py", line 59, in get_record\n    apiResponse=APIRequest(handler_ins).get_api_response()\n', '  File "/Users/erik/VirtEnvPython/VirtEnvPy/lib/python3.7/site-packages/zcrmsdk/Request.py", line 58, in get_api_response\n    CommonUtil.raise_exception(self.url,ex.message,traceback.format_stack())\n']
2020-04-29 19:35:47,469 - Client_Library - ERROR - Refresh token not provided!; Exception Message::Error occurred for https://www.zohoapis.com/crm/v2/Invoices/3719520000000276035. Error Code: 0 Response error_content: None. Error Details::['  File "test.py", line 20, in <module>\n    lead_response = lead_record_instance.get()\n', '  File "/Users/erik/VirtEnvPython/VirtEnvPy/lib/python3.7/site-packages/zcrmsdk/Operations.py", line 303, in get\n    return EntityAPIHandler.get_instance(self).get_record()\n', '  File "/Users/erik/VirtEnvPython/VirtEnvPy/lib/python3.7/site-packages/zcrmsdk/Handler.py", line 59, in get_record\n    apiResponse=APIRequest(handler_ins).get_api_response()\n', '  File "/Users/erik/VirtEnvPython/VirtEnvPy/lib/python3.7/site-packages/zcrmsdk/Request.py", line 58, in get_api_response\n    CommonUtil.raise_exception(self.url,ex.message,traceback.format_stack())\n']
2020-04-29 19:57:59,329 - Client_Library - ERROR - Refresh token not provided!; Exception Message::Error occurred for https://www.zohoapis.com/crm/v2/Accounts/4391497000000503558. Error Code: 0 Response error_content: None. Error Details::['  File "test.py", line 20, in <module>\n    lead_response = lead_record_instance.get()\n', '  File "/Users/erik/VirtEnvPython/VirtEnvPy/lib/python3.7/site-packages/zcrmsdk/Operations.py", line 303, in get\n    return EntityAPIHandler.get_instance(self).get_record()\n', '  File "/Users/erik/VirtEnvPython/VirtEnvPy/lib/python3.7/site-packages/zcrmsdk/Handler.py", line 59, in get_record\n    apiResponse=APIRequest(handler_ins).get_api_response()\n', '  File "/Users/erik/VirtEnvPython/VirtEnvPy/lib/python3.7/site-packages/zcrmsdk/Request.py", line 58, in get_api_response\n    CommonUtil.raise_exception(self.url,ex.message,traceback.format_stack())\n']
2020-04-29 19:58:52,088 - Client_Library - ERROR - Refresh token not provided!; Exception Message::Error occurred for https://www.zohoapis.com/crm/v2/Accounts/4391497000000503558. Error Code: 0 Response error_content: None. Error Details::['  File "test.py", line 20, in <module>\n    lead_response = lead_record_instance.get()\n', '  File "/Users/erik/VirtEnvPython/VirtEnvPy/lib/python3.7/site-packages/zcrmsdk/Operations.py", line 303, in get\n    return EntityAPIHandler.get_instance(self).get_record()\n', '  File "/Users/erik/VirtEnvPython/VirtEnvPy/lib/python3.7/site-packages/zcrmsdk/Handler.py", line 59, in get_record\n    apiResponse=APIRequest(handler_ins).get_api_response()\n', '  File "/Users/erik/VirtEnvPython/VirtEnvPy/lib/python3.7/site-packages/zcrmsdk/Request.py", line 58, in get_api_response\n    CommonUtil.raise_exception(self.url,ex.message,traceback.format_stack())\n']
2020-04-29 20:07:36,345 - Client_Library - ERROR - Refresh token not provided!; Exception Message::Error occurred for https://www.zohoapis.com/crm/v2/Clientes/4391497000000436001. Error Code: 0 Response error_content: None. Error Details::['  File "test.py", line 20, in <module>\n    lead_response = lead_record_instance.get()\n', '  File "/Users/erik/VirtEnvPython/VirtEnvPy/lib/python3.7/site-packages/zcrmsdk/Operations.py", line 303, in get\n    return EntityAPIHandler.get_instance(self).get_record()\n', '  File "/Users/erik/VirtEnvPython/VirtEnvPy/lib/python3.7/site-packages/zcrmsdk/Handler.py", line 59, in get_record\n    apiResponse=APIRequest(handler_ins).get_api_response()\n', '  File "/Users/erik/VirtEnvPython/VirtEnvPy/lib/python3.7/site-packages/zcrmsdk/Request.py", line 58, in get_api_response\n    CommonUtil.raise_exception(self.url,ex.message,traceback.format_stack())\n']
2020-04-29 23:56:45,259 - Client_Library - ERROR - Refresh token not provided!; Exception Message::Error occurred for https://www.zohoapis.com/crm/v2/settings/modules. Error Code: 0 Response error_content: None. Error Details::['  File "test.py", line 19, in <module>\n    resp = ZCRMRestClient.get_instance().get_all_modules()\n', '  File "/Users/erik/VirtEnvPython/VirtEnvPy/lib/python3.7/site-packages/zcrmsdk/RestClient.py", line 34, in get_all_modules\n    return MetaDataAPIHandler.get_instance().get_all_modules()\n', '  File "/Users/erik/VirtEnvPython/VirtEnvPy/lib/python3.7/site-packages/zcrmsdk/Handler.py", line 1810, in get_all_modules\n    bulk_api_response=APIRequest(handler_ins).get_bulk_api_response()\n', '  File "/Users/erik/VirtEnvPython/VirtEnvPy/lib/python3.7/site-packages/zcrmsdk/Request.py", line 74, in get_bulk_api_response\n    CommonUtil.raise_exception(self.url,ex.message,traceback.format_stack())\n']
2020-05-05 15:54:37,966 - Client_Library - ERROR - Refresh token not provided!; Exception Message::Error occurred for https://www.zohoapis.com/crm/v2/Invoices. Error Code: 0 Response error_content: None. Error Details::['  File "test.py", line 20, in <module>\n    resp = module_ins.get_records()\n', '  File "/Users/erik/VirtEnvPython/VirtEnvPy/lib/python3.7/site-packages/zcrmsdk/Operations.py", line 64, in get_records\n    return MassEntityAPIHandler.get_instance(self).get_records(cvid,sort_by,sort_order,page,per_page,custom_headers)\n', '  File "/Users/erik/VirtEnvPython/VirtEnvPy/lib/python3.7/site-packages/zcrmsdk/Handler.py", line 934, in get_records\n    bulk_api_response=APIRequest(handler_ins).get_bulk_api_response()\n', '  File "/Users/erik/VirtEnvPython/VirtEnvPy/lib/python3.7/site-packages/zcrmsdk/Request.py", line 74, in get_bulk_api_response\n    CommonUtil.raise_exception(self.url,ex.message,traceback.format_stack())\n']
2020-05-05 15:55:43,193 - Client_Library - ERROR - Refresh token not provided!; Exception Message::Error occurred for https://www.zohoapis.com/crm/v2/Invoices. Error Code: 0 Response error_content: None. Error Details::['  File "test.py", line 20, in <module>\n    resp = module_ins.get_records()\n', '  File "/Users/erik/VirtEnvPython/VirtEnvPy/lib/python3.7/site-packages/zcrmsdk/Operations.py", line 64, in get_records\n    return MassEntityAPIHandler.get_instance(self).get_records(cvid,sort_by,sort_order,page,per_page,custom_headers)\n', '  File "/Users/erik/VirtEnvPython/VirtEnvPy/lib/python3.7/site-packages/zcrmsdk/Handler.py", line 934, in get_records\n    bulk_api_response=APIRequest(handler_ins).get_bulk_api_response()\n', '  File "/Users/erik/VirtEnvPython/VirtEnvPy/lib/python3.7/site-packages/zcrmsdk/Request.py", line 74, in get_bulk_api_response\n    CommonUtil.raise_exception(self.url,ex.message,traceback.format_stack())\n']
2020-05-05 15:59:26,093 - Client_Library - ERROR - Refresh token not provided!; Exception Message::Error occurred for https://www.zohoapis.com/crm/v2/Invoices. Error Code: 0 Response error_content: None. Error Details::['  File "test.py", line 21, in <module>\n    resp = module_ins.get_records()\n', '  File "/Users/erik/VirtEnvPython/VirtEnvPy/lib/python3.7/site-packages/zcrmsdk/Operations.py", line 64, in get_records\n    return MassEntityAPIHandler.get_instance(self).get_records(cvid,sort_by,sort_order,page,per_page,custom_headers)\n', '  File "/Users/erik/VirtEnvPython/VirtEnvPy/lib/python3.7/site-packages/zcrmsdk/Handler.py", line 934, in get_records\n    bulk_api_response=APIRequest(handler_ins).get_bulk_api_response()\n', '  File "/Users/erik/VirtEnvPython/VirtEnvPy/lib/python3.7/site-packages/zcrmsdk/Request.py", line 74, in get_bulk_api_response\n    CommonUtil.raise_exception(self.url,ex.message,traceback.format_stack())\n']
2020-05-05 16:00:27,712 - Client_Library - ERROR - Refresh token not provided!; Exception Message::Error occurred for https://www.zohoapis.com/crm/v2/accounts. Error Code: 0 Response error_content: None. Error Details::['  File "test.py", line 21, in <module>\n    resp = module_ins.get_records()\n', '  File "/Users/erik/VirtEnvPython/VirtEnvPy/lib/python3.7/site-packages/zcrmsdk/Operations.py", line 64, in get_records\n    return MassEntityAPIHandler.get_instance(self).get_records(cvid,sort_by,sort_order,page,per_page,custom_headers)\n', '  File "/Users/erik/VirtEnvPython/VirtEnvPy/lib/python3.7/site-packages/zcrmsdk/Handler.py", line 934, in get_records\n    bulk_api_response=APIRequest(handler_ins).get_bulk_api_response()\n', '  File "/Users/erik/VirtEnvPython/VirtEnvPy/lib/python3.7/site-packages/zcrmsdk/Request.py", line 74, in get_bulk_api_response\n    CommonUtil.raise_exception(self.url,ex.message,traceback.format_stack())\n']
2020-05-05 16:00:29,450 - Client_Library - ERROR - Refresh token not provided!; Exception Message::Error occurred for https://www.zohoapis.com/crm/v2/accounts. Error Code: 0 Response error_content: None. Error Details::['  File "test.py", line 21, in <module>\n    resp = module_ins.get_records()\n', '  File "/Users/erik/VirtEnvPython/VirtEnvPy/lib/python3.7/site-packages/zcrmsdk/Operations.py", line 64, in get_records\n    return MassEntityAPIHandler.get_instance(self).get_records(cvid,sort_by,sort_order,page,per_page,custom_headers)\n', '  File "/Users/erik/VirtEnvPython/VirtEnvPy/lib/python3.7/site-packages/zcrmsdk/Handler.py", line 934, in get_records\n    bulk_api_response=APIRequest(handler_ins).get_bulk_api_response()\n', '  File "/Users/erik/VirtEnvPython/VirtEnvPy/lib/python3.7/site-packages/zcrmsdk/Request.py", line 74, in get_bulk_api_response\n    CommonUtil.raise_exception(self.url,ex.message,traceback.format_stack())\n']
2020-05-05 16:18:16,441 - Client_Library - ERROR - Refresh token not provided!; Exception Message::Error occurred for https://www.zohoapis.com/crm/v2/Accounts. Error Code: 0 Response error_content: None. Error Details::['  File "connection.py", line 25, in <module>\n    resp = module_ins.get_records()\n', '  File "/Users/erik/VirtEnvPython/VirtEnvPy/lib/python3.7/site-packages/zcrmsdk/Operations.py", line 64, in get_records\n    return MassEntityAPIHandler.get_instance(self).get_records(cvid,sort_by,sort_order,page,per_page,custom_headers)\n', '  File "/Users/erik/VirtEnvPython/VirtEnvPy/lib/python3.7/site-packages/zcrmsdk/Handler.py", line 934, in get_records\n    bulk_api_response=APIRequest(handler_ins).get_bulk_api_response()\n', '  File "/Users/erik/VirtEnvPython/VirtEnvPy/lib/python3.7/site-packages/zcrmsdk/Request.py", line 74, in get_bulk_api_response\n    CommonUtil.raise_exception(self.url,ex.message,traceback.format_stack())\n']
2020-05-05 16:36:06,630 - Client_Library - ERROR - Refresh token not provided!; Exception Message::Error occurred for https://www.zohoapis.com/crm/v2/Invoices. Error Code: 0 Response error_content: None. Error Details::['  File "test.py", line 20, in <module>\n    resp = module_ins.get_records()\n', '  File "/Users/erik/VirtEnvPython/VirtEnvPy/lib/python3.7/site-packages/zcrmsdk/Operations.py", line 64, in get_records\n    return MassEntityAPIHandler.get_instance(self).get_records(cvid,sort_by,sort_order,page,per_page,custom_headers)\n', '  File "/Users/erik/VirtEnvPython/VirtEnvPy/lib/python3.7/site-packages/zcrmsdk/Handler.py", line 934, in get_records\n    bulk_api_response=APIRequest(handler_ins).get_bulk_api_response()\n', '  File "/Users/erik/VirtEnvPython/VirtEnvPy/lib/python3.7/site-packages/zcrmsdk/Request.py", line 74, in get_bulk_api_response\n    CommonUtil.raise_exception(self.url,ex.message,traceback.format_stack())\n']
2020-05-05 16:37:12,734 - Client_Library - ERROR - Refresh token not provided!; Exception Message::Error occurred for https://www.zohoapis.com/crm/v2/Invoices. Error Code: 0 Response error_content: None. Error Details::['  File "connection.py", line 24, in <module>\n    resp = module_ins.get_records()\n', '  File "/Users/erik/VirtEnvPython/VirtEnvPy/lib/python3.7/site-packages/zcrmsdk/Operations.py", line 64, in get_records\n    return MassEntityAPIHandler.get_instance(self).get_records(cvid,sort_by,sort_order,page,per_page,custom_headers)\n', '  File "/Users/erik/VirtEnvPython/VirtEnvPy/lib/python3.7/site-packages/zcrmsdk/Handler.py", line 934, in get_records\n    bulk_api_response=APIRequest(handler_ins).get_bulk_api_response()\n', '  File "/Users/erik/VirtEnvPython/VirtEnvPy/lib/python3.7/site-packages/zcrmsdk/Request.py", line 74, in get_bulk_api_response\n    CommonUtil.raise_exception(self.url,ex.message,traceback.format_stack())\n']
2020-05-05 16:40:13,163 - Client_Library - ERROR - Refresh token not provided!; Exception Message::Error occurred for https://www.zohoapis.com/crm/v2/Invoices. Error Code: 0 Response error_content: None. Error Details::['  File "connection.py", line 24, in <module>\n    resp = module_ins.get_records()\n', '  File "/Users/erik/VirtEnvPython/VirtEnvPy/lib/python3.7/site-packages/zcrmsdk/Operations.py", line 64, in get_records\n    return MassEntityAPIHandler.get_instance(self).get_records(cvid,sort_by,sort_order,page,per_page,custom_headers)\n', '  File "/Users/erik/VirtEnvPython/VirtEnvPy/lib/python3.7/site-packages/zcrmsdk/Handler.py", line 934, in get_records\n    bulk_api_response=APIRequest(handler_ins).get_bulk_api_response()\n', '  File "/Users/erik/VirtEnvPython/VirtEnvPy/lib/python3.7/site-packages/zcrmsdk/Request.py", line 74, in get_bulk_api_response\n    CommonUtil.raise_exception(self.url,ex.message,traceback.format_stack())\n']
2020-05-05 17:54:09,981 - Client_Library - ERROR - Refresh token not provided!; Exception Message::Error occurred for https://www.zohoapis.com/crm/v2/Invoices. Error Code: 0 Response error_content: None. Error Details::['  File "test.py", line 20, in <module>\n    resp = module_ins.get_records()\n', '  File "/Users/erik/VirtEnvPython/VirtEnvPy/lib/python3.7/site-packages/zcrmsdk/Operations.py", line 64, in get_records\n    return MassEntityAPIHandler.get_instance(self).get_records(cvid,sort_by,sort_order,page,per_page,custom_headers)\n', '  File "/Users/erik/VirtEnvPython/VirtEnvPy/lib/python3.7/site-packages/zcrmsdk/Handler.py", line 934, in get_records\n    bulk_api_response=APIRequest(handler_ins).get_bulk_api_response()\n', '  File "/Users/erik/VirtEnvPython/VirtEnvPy/lib/python3.7/site-packages/zcrmsdk/Request.py", line 74, in get_bulk_api_response\n    CommonUtil.raise_exception(self.url,ex.message,traceback.format_stack())\n']
2020-05-05 17:55:37,697 - Client_Library - ERROR - Refresh token not provided!; Exception Message::Error occurred for https://www.zohoapis.com/crm/v2/Invoices. Error Code: 0 Response error_content: None. Error Details::['  File "test.py", line 24, in <module>\n    resp = module_ins.get_records()\n', '  File "/Users/erik/VirtEnvPython/VirtEnvPy/lib/python3.7/site-packages/zcrmsdk/Operations.py", line 64, in get_records\n    return MassEntityAPIHandler.get_instance(self).get_records(cvid,sort_by,sort_order,page,per_page,custom_headers)\n', '  File "/Users/erik/VirtEnvPython/VirtEnvPy/lib/python3.7/site-packages/zcrmsdk/Handler.py", line 934, in get_records\n    bulk_api_response=APIRequest(handler_ins).get_bulk_api_response()\n', '  File "/Users/erik/VirtEnvPython/VirtEnvPy/lib/python3.7/site-packages/zcrmsdk/Request.py", line 74, in get_bulk_api_response\n    CommonUtil.raise_exception(self.url,ex.message,traceback.format_stack())\n']
2020-05-22 14:09:07,769 - Client_Library - ERROR - Refresh token not provided!; Exception Message::Error occurred for https://www.zohoapis.com/crm/v2/Accounts. Error Code: 0 Response error_content: None. Error Details::['  File "consult_insert_db.py", line 22, in <module>\n    resp = module_ins.get_records()\n', '  File "/Users/erik/VirtEnvPython/VirtEnvPy/lib/python3.7/site-packages/zcrmsdk/Operations.py", line 64, in get_records\n    return MassEntityAPIHandler.get_instance(self).get_records(cvid,sort_by,sort_order,page,per_page,custom_headers)\n', '  File "/Users/erik/VirtEnvPython/VirtEnvPy/lib/python3.7/site-packages/zcrmsdk/Handler.py", line 934, in get_records\n    bulk_api_response=APIRequest(handler_ins).get_bulk_api_response()\n', '  File "/Users/erik/VirtEnvPython/VirtEnvPy/lib/python3.7/site-packages/zcrmsdk/Request.py", line 74, in get_bulk_api_response\n    CommonUtil.raise_exception(self.url,ex.message,traceback.format_stack())\n']
